<?xml version='1.0' encoding='utf-8'?>
<robot name="7dof_urdf">
    <link name="link_2">
        <inertial>
            <origin xyz="-0.03952607880115397 -7.87183651596024e-11 -0.02500000543490777" rpy="0.0 -0.0 0.0" />
            <mass value="2.979882734992265" />
            <inertia ixx="0.004109388239766435" iyy="0.006418233610608557" izz="0.004957923706044316" ixy="-3.215653177762734e-11" iyz="-8.44506700407332e-11" ixz="-1.779046010140983e-10" />
        </inertial>
        <visual name="link_2_visual">
            <origin xyz="-0.085 0.0 -0.024999999999999974" rpy="-0.0 1.5707963267948966 0" />
            <geometry>
                <mesh filename="meshes/link_2.stl" scale="0.001 0.001 0.001" />
            </geometry>
        </visual>
        <collision name="link_2_collision">
            <origin xyz="-0.085 0.0 -0.024999999999999974" rpy="-0.0 1.5707963267948966 0" />
            <geometry>
                <mesh filename="meshes/link_2.stl" scale="0.001 0.001 0.001" />
            </geometry>
        </collision>
    </link>
    <link name="link_1">
        <inertial>
            <origin xyz="-1.3358453465197302e-13 -1.2510643917589552e-10 0.05584017422892464" rpy="0.0 -0.0 0.0" />
            <mass value="4.5781679249113525" />
            <inertia ixx="0.008836478951234468" iyy="0.007460759562605522" izz="0.0040259717554885655" ixy="-9.516813834048548e-12" iyz="-8.319163950537849e-12" ixz="-3.1370176836326214e-14" />
        </inertial>
        <visual name="link_1_visual">
            <origin xyz="0.0 0.0 0.13" rpy="-1.5707963267948966 -0.0 0.0" />
            <geometry>
                <mesh filename="meshes/link_1.stl" scale="0.001 0.001 0.001" />
            </geometry>
        </visual>
        <collision name="link_1_collision">
            <origin xyz="0.0 0.0 0.13" rpy="-1.5707963267948966 -0.0 0.0" />
            <geometry>
                <mesh filename="meshes/link_1.stl" scale="0.001 0.001 0.001" />
            </geometry>
        </collision>
    </link>
    <link name="link_3">
        <inertial>
            <origin xyz="0.006313001202569603 -5.37863572347419e-09 0.09373395234679954" rpy="0.0 -0.0 0.0" />
            <mass value="9.849367155912846" />
            <inertia ixx="0.03793714589399133" iyy="0.039672677743592566" izz="0.010979504330028436" ixy="1.0419039199981162e-08" iyz="-1.5181024909383112e-09" ixz="-0.004960191886071146" />
        </inertial>
        <visual name="link_3_visual">
            <origin xyz="-2.6645352591003756e-17 8.881784197001253e-18 -1.7763568394002505e-17" rpy="3.141592653589793 -0.0 0.0" />
            <geometry>
                <mesh filename="meshes/link_3.stl" scale="0.001 0.001 0.001" />
            </geometry>
        </visual>
        <collision name="link_3_collision">
            <origin xyz="-2.6645352591003756e-17 8.881784197001253e-18 -1.7763568394002505e-17" rpy="3.141592653589793 -0.0 0.0" />
            <geometry>
                <mesh filename="meshes/link_3.stl" scale="0.001 0.001 0.001" />
            </geometry>
        </collision>
    </link>
    <link name="link_4">
        <inertial>
            <origin xyz="0.04846683466566324 -0.03293830778022692 -0.02499998900129377" rpy="0.0 -0.0 0.0" />
            <mass value="4.2776469384488465" />
            <inertia ixx="0.005985395948107042" iyy="0.008304810056541968" izz="0.00773545938265402" ixy="0.0014843269663658287" iyz="1.4692520949877164e-09" ixz="1.942723766579224e-09" />
        </inertial>
        <visual name="link_4_visual">
            <origin xyz="-1.7763568394002505e-17 -7.105427357601002e-17 -0.02499999999999999" rpy="-1.5707963267948966 -0.0 0.0" />
            <geometry>
                <mesh filename="meshes/link_4.stl" scale="0.001 0.001 0.001" />
            </geometry>
        </visual>
        <collision name="link_4_collision">
            <origin xyz="-1.7763568394002505e-17 -7.105427357601002e-17 -0.02499999999999999" rpy="-1.5707963267948966 -0.0 0.0" />
            <geometry>
                <mesh filename="meshes/link_4.stl" scale="0.001 0.001 0.001" />
            </geometry>
        </collision>
    </link>
    <link name="link_5-v1">
        <inertial>
            <origin xyz="-1.062326191458851e-09 7.241709543137631e-10 0.029282930406813037" rpy="0.0 -0.0 0.0" />
            <mass value="1.2770023533463133" />
            <inertia ixx="0.0011243052012639768" iyy="0.001737633001188288" izz="0.00146306717322775" ixy="-1.9080084734390823e-12" iyz="1.9818700500162656e-11" ixz="-2.790700309729388e-11" />
        </inertial>
        <visual name="link_5-v1_visual">
            <origin xyz="-1.7763568394002506e-16 1.2434497875801754e-16 0.0" rpy="0.0 -0.0 3.141592653589793" />
            <geometry>
                <mesh filename="meshes/link_5-v1.stl" scale="0.001 0.001 0.001" />
            </geometry>
        </visual>
        <collision name="link_5-v1_collision">
            <origin xyz="-1.7763568394002506e-16 1.2434497875801754e-16 0.0" rpy="0.0 -0.0 3.141592653589793" />
            <geometry>
                <mesh filename="meshes/link_5-v1.stl" scale="0.001 0.001 0.001" />
            </geometry>
        </collision>
    </link>
    <link name="link_6-v1">
        <inertial>
            <origin xyz="0.025005212281838853 -1.911312160984835e-08 -0.03321313333405687" rpy="0.0 -0.0 0.0" />
            <mass value="3.493951944589778" />
            <inertia ixx="0.006949534318566569" iyy="0.006734705172640132" izz="0.0018937373742333174" ixy="1.5093234301266634e-10" iyz="-1.7548580921733503e-09" ixz="3.373713313992166e-07" />
        </inertial>
        <visual name="link_6-v1_visual">
            <origin xyz="0.02499999999999986 -6.217248937900877e-17 1.4210854715202004e-16" rpy="-1.5707963267948968 -3.0189874454731085e-48 -3.141592653589793" />
            <geometry>
                <mesh filename="meshes/link_6-v1.stl" scale="0.001 0.001 0.001" />
            </geometry>
        </visual>
        <collision name="link_6-v1_collision">
            <origin xyz="0.02499999999999986 -6.217248937900877e-17 1.4210854715202004e-16" rpy="-1.5707963267948968 -3.0189874454731085e-48 -3.141592653589793" />
            <geometry>
                <mesh filename="meshes/link_6-v1.stl" scale="0.001 0.001 0.001" />
            </geometry>
        </collision>
    </link>
    <link name="link_7-v1">
        <inertial>
            <origin xyz="0.023421590518569707 0.024999677602399677 5.6249555768772554e-08" rpy="0.0 -0.0 0.0" />
            <mass value="0.6086791712424446" />
            <inertia ixx="0.0004926964088955016" iyy="0.0003514587577441164" izz="0.0005842271225232135" ixy="-3.5404794321985955e-09" iyz="4.2253265122860206e-11" ixz="6.19772733134738e-10" />
        </inertial>
        <visual name="link_7-v1_visual">
            <origin xyz="-0.03500000000000014 0.025000000000001174 -1.4210854715202004e-16" rpy="1.5707963267948968 1.224646799147352e-16 1.5707963267948968" />
            <geometry>
                <mesh filename="meshes/link_7-v1.stl" scale="0.001 0.001 0.001" />
            </geometry>
        </visual>
        <collision name="link_7-v1_collision">
            <origin xyz="-0.03500000000000014 0.025000000000001174 -1.4210854715202004e-16" rpy="1.5707963267948968 1.224646799147352e-16 1.5707963267948968" />
            <geometry>
                <mesh filename="meshes/link_7-v1.stl" scale="0.001 0.001 0.001" />
            </geometry>
        </collision>
    </link>
    <link name="end_effector-v1">
        <inertial>
            <origin xyz="0.007808473753499534 1.1990408665951691e-15 -1.4210854715202004e-16" rpy="0.0 -0.0 0.0" />
            <mass value="0.1100832579791584" />
            <inertia ixx="3.0965331709110686e-05" iyy="2.061833240113442e-05" izz="2.8644659203503828e-05" ixy="-2.168404344971009e-19" iyz="2.168404344971009e-19" ixz="-2.8774653041494396e-37" />
        </inertial>
        <visual name="end_effector-v1_visual">
            <origin xyz="-1.4210854715202004e-16 1.2079226507921704e-15 -1.4210854715202004e-16" rpy="-6.123233995736766e-17 1.5707963267948966 0" />
            <geometry>
                <mesh filename="meshes/end_effector-v1.stl" scale="0.001 0.001 0.001" />
            </geometry>
        </visual>
        <collision name="end_effector-v1_collision">
            <origin xyz="-1.4210854715202004e-16 1.2079226507921704e-15 -1.4210854715202004e-16" rpy="-6.123233995736766e-17 1.5707963267948966 0" />
            <geometry>
                <mesh filename="meshes/end_effector-v1.stl" scale="0.001 0.001 0.001" />
            </geometry>
        </collision>
    </link>
    <link name="base_link">
        <inertial>
            <origin xyz="8.797664231078658e-18 0.135 0.0" rpy="0.0 0.0 0.0" />
            <mass value="0.5072037603811039" />
            <inertia ixx="0.00026609900447170827" iyy="0.0005237446129370653" izz="0.00026609900447170827" ixy="2.6773250283440574e-19" iyz="3.346656285430072e-19" ixz="0.0" />
        </inertial>
        <visual name="base_link_visual">
            <origin xyz="0.0 0.0 0.0" rpy="0.0 0.0 0.0" />
            <geometry>
                <mesh filename="meshes/base_link.stl" scale="0.001 0.001 0.001" />
            </geometry>
        </visual>
        <collision name="base_link_collision">
            <origin xyz="0.0 0.0 0.0" rpy="0.0 0.0 0.0" />
            <geometry>
                <mesh filename="meshes/base_link.stl" scale="0.001 0.001 0.001" />
            </geometry>
        </collision>
    </link>
  <joint name="joint_2" type="revolute">
        <origin xyz="-0.025 0.0 0.085" rpy="-1.5707963267948966 -0.0 1.5707963267948966" />
        <parent link="link_1" />
        <child link="link_2" />
        <axis xyz="0.0 0.0 1.0" />
        <limit lower="-3.141592653589793" upper="3.141592653589793" effort="50" velocity="2.0" />
    </joint>

    <joint name="joint_3" type="revolute">
        <origin xyz="-0.085 0.0 -0.025" rpy="-3.141592653589793 1.5707963267948966 0" />
        <parent link="link_2" />
        <child link="link_3" />
        <axis xyz="0.0 0.0 1.0" />
        <limit lower="-3.141592653589793" upper="3.141592653589793" effort="50" velocity="2.0" />
    </joint>

    <joint name="joint_4" type="revolute">
        <origin xyz="0.03 0.025 0.18" rpy="-1.5707963267948966 -0.0 0.0" />
        <parent link="link_3" />
        <child link="link_4" />
        <axis xyz="0.0 0.0 1.0" />
        <limit lower="-3.141592653589793" upper="1.13" effort="50" velocity="2.0" />
    </joint>

    <joint name="joint_5" type="revolute">
        <origin xyz="0.1 -0.04 -0.025" rpy="1.5707963267948966 -0.0 1.5707963267948966" />
        <parent link="link_4" />
        <child link="link_5-v1" />
        <axis xyz="0.0 0.0 1.0" />
        <limit lower="-3.141592653589793" upper="3.141592653589793" effort="50" velocity="2.0" />
    </joint>

    <joint name="joint_6" type="revolute">
        <origin xyz="-0.025 0.0 0.05" rpy="-3.141592653589793 -0.0 0.0" />
        <parent link="link_5-v1" />
        <child link="link_6-v1" />
        <axis xyz="1.0 0.0 0.0" />
        <limit lower="-3.141592653589793" upper="3.141592653589793" effort="50" velocity="2.0" />
    </joint>

    <joint name="joint_7" type="revolute">
        <origin xyz="0.025 -0.025 -0.07600000000000001" rpy="9.183380086633855e-49 1.5707963267948966 0" />
        <parent link="link_6-v1" />
        <child link="link_7-v1" />
        <axis xyz="0.0 -1.0 9.183380086633855e-49" />
        <limit lower="-3.141592653589793" upper="3.141592653589793" effort="50" velocity="2.0" />
    </joint>

    <joint name="joint_8" type="revolute">
        <origin xyz="0.045 0.025 0.0" rpy="0.0 4.8271527307690255e-33 -4.4329578262884505e-81" />
        <parent link="link_7-v1" />
        <child link="end_effector-v1" />
        <axis xyz="1.0 0.0 -4.8271527307690255e-33" />
        <limit lower="-3.141592653589793" upper="3.141592653589793" effort="50" velocity="2.0" />
    </joint>

    <joint name="joint_1" type="revolute">
        <origin xyz="0.0 0.13 0.0" rpy="1.5707963267948966 -0.0 0.0" />
        <parent link="base_link" />
        <child link="link_1" />
        <axis xyz="0.0 0.0 1.0" />
        <limit lower="-3.141592653589793" upper="3.141592653589793" effort="50" velocity="2.0" />
    </joint>
</robot>